<robot name="gurdy">

    <gazebo>
        <plugin name="gazebo_ros_control" filename="libgazebo_ros_control.so">
        </plugin>
    </gazebo>
	<!-- * * * Link Definitions * * * -->

    <link name="world"/>

    <link name="x_axis_link">
 	    <inertial>
            <origin rpy="0.0 0 0" xyz="0 0 0"/>
            <mass value="0.01" />
            <inertia ixx="7.58333333333e-07" ixy="0.0" ixz="0.0" iyy="7.58333333333e-07" iyz="0.0" izz="1.25e-06"/>
        </inertial>
        <collision>
            <origin rpy="0.0 0 0" xyz="0 0 0"/>
            <geometry>
                <box size="1.0 1.0 0.01"/>
            </geometry>
        </collision>
        <visual>
            <origin rpy="0.0 0 0" xyz="0 0 0"/>
            <geometry>
                <box size="1.0 1.0 0.01"/>
            </geometry>
        </visual>
	</link>

    <gazebo reference="x_axis_link">
        <mu1>10.0</mu1>
        <mu2>10.0</mu2>
        <material>Gazebo/Red</material>
    </gazebo>

    <joint name="x_axis_joint" type="prismatic">
        <origin xyz="0 0 0.01" rpy="0.0 0.0 0.0"/>
        <parent link="world" />
        <child link="x_axis_link" />
        <axis xyz="1 0 0" />
        <limit effort="10000" lower="-5.0" upper="5.0" velocity="1" />
        <!--<dynamics damping="100.0" />-->
    </joint>


    <transmission name="tran1">
        <type>transmission_interface/SimpleTransmission</type>
        <joint name="x_axis_joint">
            <hardwareInterface>EffortJointInterface</hardwareInterface>
        </joint>
        <actuator name="motor1">
            <hardwareInterface>EffortJointInterface</hardwareInterface>
            <mechanicalReduction>1</mechanicalReduction>
        </actuator>
    </transmission>

    <link name="y_axis_link">
 	    <inertial>
            <origin rpy="0.0 0 0" xyz="0 0 0"/>
            <mass value="0.01" />
            <inertia ixx="7.58333333333e-07" ixy="0.0" ixz="0.0" iyy="7.58333333333e-07" iyz="0.0" izz="1.25e-06"/>
        </inertial>
        <collision>
            <origin rpy="0.0 0 0" xyz="0 0 0"/>
            <geometry>
                <box size="1.0 1.0 0.01"/>
            </geometry>
        </collision>
        <visual>
            <origin rpy="0.0 0 0" xyz="0 0 0"/>
            <geometry>
                <box size="1.0 1.0 0.01"/>
            </geometry>
        </visual>
	</link>

    <gazebo reference="y_axis_link">
        <mu1>10.0</mu1>
        <mu2>10.0</mu2>
        <material>Gazebo/Green</material>
        <self_collide>0</self_collide>
    </gazebo>

    <joint name="y_axis_joint" type="prismatic">
        <origin xyz="0 0 0.01" rpy="0.0 0.0 0.0"/>
        <parent link="x_axis_link" />
        <child link="y_axis_link" />
        <axis xyz="0 1 0" />
        <limit effort="10000" lower="-5.0" upper="5.0" velocity="1" />
        <!--<dynamics damping="100.0" />-->
    </joint>


    <transmission name="tran2">
        <type>transmission_interface/SimpleTransmission</type>
        <joint name="y_axis_joint">
            <hardwareInterface>EffortJointInterface</hardwareInterface>
        </joint>
        <actuator name="motor2">
            <hardwareInterface>EffortJointInterface</hardwareInterface>
            <mechanicalReduction>1</mechanicalReduction>
        </actuator>
    </transmission>


    <link name="entity_link">
 	    <inertial>
            <origin rpy="0.0 0 0" xyz="0 0 0"/>
            <mass value="0.1" />
            <inertia ixx="4.16666666667e-05" ixy="0.0" ixz="0.0" iyy="4.16666666667e-05" iyz="0.0" izz="4.16666666667e-05"/>
        </inertial>

        <visual>
            <origin rpy="0.0 0 0" xyz="0 0 0"/>
            <geometry>
                <box size="0.05 0.05 0.05"/>
            </geometry>
        </visual>
	</link>

    <gazebo reference="entity_link">
        <mu1>10.0</mu1>
        <mu2>10.0</mu2>
        <material>Gazebo/Blue</material>
    </gazebo>

    <joint name="entity_link_joint" type="fixed">
        <parent link="y_axis_link"/>
        <child link="entity_link"/>
        <origin xyz="0 0 0.025" rpy="0 0 0"/>
    </joint>



</robot>